Workbook
Name name: [1]Sheet1!$A$2:$A$4
Name type: [1]Sheet1!$A$3:$A$4

Sheet Sheet1
A1: KMS | B1: Hours
A3: 161-193 | B3: 5
A4: 193-225 | B4: 6
A5: 225-257 | B5: 7
A6: 257-290 | B6: 8
A7: 290-322 | B7: 9
A8: 322-338 | B8: 10
A9: 338-354 | B9: 10.5
A10: 354-370 | B10: 11
A11: 370-386 | B11: 11.5
A12: 386-402 | B12: 12
A13: 402-418 | B13: 12.5
A14: 418-435 | B14: 13
... A27: 628-644 | B27: 19.5

Sheet Trial
A1: PAY PERIOD | C1: 44297 | F1: =A16 -> 44310 | I1: 1
A2: Date | B2: Day | C2: Rostered Start time | D2: Rostered End time | E2: Rostered Hours | F2: Actual Start Time | G2: Actual End Time | H2: Ordinary hours | I2: before midnight | J2: after midnight | K2: Mileage | L2: Callout Allowance | M2: Extra Shift | N2: PH | O2: SL/PHNW | P2: AL | Q2: Layback/Liftup | R2: Layback | S2: Overtime Hours | T2: Overtime Hours | U2: Total OT | V2: Actual Hours | W2: Actual hours worked | X2: Morning | Y2: Afternoon | Z2: Night | AA2: Special Loading | AB2: 8 Hour Mark | AC2: Mileage Time
A3: =C1 -> 44297 | B3: Sun | C3: 0.70833333 | D3: 0.096527778 | E3: =((D3-C3+(C3>D3))*24) -> 9.3166667 | H3: =IF(OR(M3>0,N3>0),0,IF(W3>8,8,($E3-$T3))) -> 8 | I3: =IF(G3<F3,($I$1-F3)*24,IF(D3<C3,($I$1-C3)*24,0)) -> 7 | J3: =IF(M16>0,0,IF(I16>0,IF(F16>0,W16-I16,E16-I16),0)) -> 0 | K3: 322-338 | Q3: =IF(V3>0,R3-V3,R3) -> 0 | R3: =IF(F3=0,"0",IF(F3>C3,(24*TEXT(F3-C3,"HH:MM")), (24*TEXT(D3-G3,"HH:MM")))) -> 0 | S3: =IF(M3>0,0,IF(I3>0,IF(I3>8,(I3-8),0),T3))+IF(AND(I16>0,T16>0),IF(I16>8,(T16-(I16-8)),T16),0) -> 0 | T3: =IF(M3>0,0,IF($W3>8,$W3-8,(IF(E3>8,E3-8,0)))) -> 1.3166667 | U3: =Q3+S3 -> 0 | V3: =IF(AND(F3>0, ((G3-F3+(F3>G3))*24)<8),8- ((G3-F3+(F3>G3))*24),0) -> 0 | W3: =((G3-F3+(F3>G3))*24) -> 0 | Y3: =IF(OR(M3>0,L3>0),0,IF(I3>0,IF($F3>0,IF(OR($F3>=$X$24,AND($Z$24<$F3,$F3<$Y$24)),ROUND(8-I3,0),0),IF($C3>0,IF(OR($C3>=$X$24,AND($Z$24<$C3,$C3<$Y$24)),ROUND(8-I3,0),0),0)),0)) -> 1 | Z3: =IF(OR(M3>0,L3>0),0,IF(I3>0,IF($F3>0,IF(OR($F3>=$X$23,AND($Z$23<$F3,$F3<$Y$23)),ROUND(8-I3,0),0),IF($C3>0,IF(OR($C3>=$X$23,AND($Z$23<$C3,$C3<$Y$23)),ROUND(8-I3,0),0),0)),0)) -> 0 | AA3: =IF(OR(L3>0,M3>0),0,IF(I3>0,IF($F3>0,IF(OR(AND($F3>$X$25,$F3<$Y$25),AND($G3>$X$25,$G3<$Y$25)),1,0),IF($C3>0,IF(OR(AND($C3>$X$25,$C3<$Y$25),AND($D3>$X$25,$D3<$Y$25)),1,0),0)),0)) -> 1 | AB3: =IF(F3>0,F3+(8/24),IF(C3>0,C3+(8/24),0)) -> 1.0416667 | AC3: =IF(IF(K3>0,VLOOKUP(K3,Sheet1!$A$3:$B$27,2,FALSE)-E3,0)>0,IF(K3>0,VLOOKUP(K3,Sheet1!$A$3:$B$27,2,FALSE)-E3,0),0) -> 0.68333333
A4: =A3+1 -> 44298 | B4: Mon | E4: =((D4-C4+(C4>D4))*24) -> 0 | H4: =IF(OR(M4>0,N4>0),0,IF(W4>8,8,($E4-$T4))) -> 0 | I4: =IF(G4<F4,($I$1-F4)*24,IF(D4<C4,($I$1-C4)*24,0)) -> 0 | J4: =IF(I3>0, IF(F3>0, W3-I3, E3-I3),0) -> 2.3166667 | Q4: =IF(V4>0,R4-V4,R4) -> 0 | R4: =IF(F4=0,"0",IF(F4>C4,(24*TEXT(F4-C4,"HH:MM")), (24*TEXT(D4-G4,"HH:MM")))) -> 0 | S4: =IF(M4>0,0,IF(I4>0,IF(I4>8,(I4-8),0),T4))+IF(AND(I3>0,T3>0),IF(I3>8,(T3-(I3-8)),T3),0) -> 1.3166667 | T4: =IF(M4>0,0,IF($W4>8,$W4-8,(IF(E4>8,E4-8,0)))) -> 0 | U4: =Q4+T4 -> 0 | V4: =IF(AND(F4>0, ((G4-F4+(F4>G4))*24)<8),8- ((G4-F4+(F4>G4))*24),0) -> 0 | W4: =((G4-F4+(F4>G4))*24) -> 0 | X4: =IF(OR(L4>0,M4>0),0,IF($F4>0,IF(AND($F4>=$X$26,$F4<=$Y$26),8,0),IF(AND($C4>=$X$26,$C4<=$Y$26),ROUND(H4,0),0))) -> 0 | Y4: =IF(OR(M4>0, L4>0),0,IF(OR(AND($C4>$X$24,$C4<$Y$24,OR($D4>$Y$24,D4>=$Z$24)),(AND($F4>$X$24,$F4<$Y$24,OR($G4>$Y$24,G4>=$Z$24)))),ROUND(H4,0),0)) -> 0 | Z4: =IF(OR(M4>0,L4>0),0,IF($F4>0,IF(OR($F4>=$X$23,AND($Z$23<$F4,$F4<$Y$23)),8,0),IF($C4>0,IF(OR($C4>=$X$23,AND($Z$23<$C4,$C4<$Y$23)),ROUND(H4,0),0),0))) -> 0 | AA4: =IF(OR(L4>0,M4>0),0,IF($F4>0,IF(OR(AND($F4>$X$25,$F4<$Y$25),AND($G4>$X$25,$G4<$Y$25)),1,0),IF($C4>0,IF(OR(AND($C4>$X$25,$C4<$Y$25),AND($D4>$X$25,$D4<$Y$25)),1,0),0))) -> 0 | AB4: =IF(F4>0,F4+(8/24),IF(C4>0,C4+(8/24),0)) -> 0 | AC4: =IF(IF(K4>0,VLOOKUP(K4,Sheet1!$A$3:$B$27,2,FALSE)-E4,0)>0,IF(K4>0,VLOOKUP(K4,Sheet1!$A$3:$B$27,2,FALSE)-E4,0),0) -> 0
A5: =A4+1 -> 44299 | B5: Tue | C5: 0.71527778 | D5: 0.071527778 | E5: =((D5-C5+(C5>D5))*24) -> 8.55 | H5: =IF(OR(M5>0,N5>0),0,IF(W5>8,8,($E5-$T5))) -> 8 | I5: =IF(G5<F5,($I$1-F5)*24,IF(D5<C5,($I$1-C5)*24,0)) -> 6.8333333 | J5: =IF(I4>0, IF(F4>0, W4-I4, E4-I4),0) -> 0 | Q5: =IF(V5>0,R5-V5,R5) -> 0 | R5: =IF(F5=0,"0",IF(F5>C5,(24*TEXT(F5-C5,"HH:MM")), (24*TEXT(D5-G5,"HH:MM")))) -> 0 | S5: =IF(M5>0,0,IF(I5>0,IF(I5>8,(I5-8),0),T5))+IF(AND(I4>0,T4>0),IF(I4>8,(T4-(I4-8)),T4),0) -> 0 | T5: =IF(M5>0,0,IF($W5>8,$W5-8,(IF(E5>8,E5-8,0)))) -> 0.55 | U5: =Q5+T5 -> 0.55 | V5: =IF(AND(F5>0, ((G5-F5+(F5>G5))*24)<8),8- ((G5-F5+(F5>G5))*24),0) -> 0 | W5: =((G5-F5+(F5>G5))*24) -> 0 | X5: =IF(OR(L5>0,M5>0),0,IF($F5>0,IF(AND($F5>=$X$26,$F5<=$Y$26),8,0),IF(AND($C5>=$X$26,$C5<=$Y$26),ROUND(H5,0),0))) -> 0 | Y5: =IF(OR(M5>0, L5>0),0,IF(OR(AND($C5>$X$24,$C5<$Y$24,OR($D5>$Y$24,D5>=$Z$24)),(AND($F5>$X$24,$F5<$Y$24,OR($G5>$Y$24,G5>=$Z$24)))),ROUND(H5,0),0)) -> 8 | Z5: =IF(OR(M5>0,L5>0),0,IF($F5>0,IF(OR($F5>=$X$23,AND($Z$23<$F5,$F5<$Y$23)),8,0),IF($C5>0,IF(OR($C5>=$X$23,AND($Z$23<$C5,$C5<$Y$23)),ROUND(H5,0),0),0))) -> 0 | AA5: =IF(OR(L5>0,M5>0),0,IF($F5>0,IF(OR(AND($F5>$X$25,$F5<$Y$25),AND($G5>$X$25,$G5<$Y$25)),1,0),IF($C5>0,IF(OR(AND($C5>$X$25,$C5<$Y$25),AND($D5>$X$25,$D5<$Y$25)),1,0),0))) -> 1 | AB5: =IF(F5>0,F5+(8/24),IF(C5>0,C5+(8/24),0)) -> 1.0486111 | AC5: =IF(IF(K5>0,VLOOKUP(K5,Sheet1!$A$3:$B$27,2,FALSE)-E5,0)>0,IF(K5>0,VLOOKUP(K5,Sheet1!$A$3:$B$27,2,FALSE)-E5,0),0) -> 0
A6: =A5+1 -> 44300 | B6: Wed | C6: 0.68263889 | D6: 0.028472222 | E6: =((D6-C6+(C6>D6))*24) -> 8.3 | H6: =IF(OR(M6>0,N6>0),0,IF(W6>8,8,($E6-$T6))) -> 8 | I6: =IF(G6<F6,($I$1-F6)*24,IF(D6<C6,($I$1-C6)*24,0)) -> 7.6166667 | J6: =IF(I5>0, IF(F5>0, W5-I5, E5-I5),0) -> 1.7166667 | K6: 290-322 | Q6: =IF(V6>0,R6-V6,R6) -> 0 | R6: =IF(F6=0,"0",IF(F6>C6,(24*TEXT(F6-C6,"HH:MM")), (24*TEXT(D6-G6,"HH:MM")))) -> 0 | S6: =IF(M6>0,0,IF(I6>0,IF(I6>8,(I6-8),0),T6))+IF(AND(I5>0,T5>0),IF(I5>8,(T5-(I5-8)),T5),0) -> 0.55 | T6: =IF(M6>0,0,IF($W6>8,$W6-8,(IF(E6>8,E6-8,0)))) -> 0.3 | U6: =Q6+T6 -> 0.3 | V6: =IF(AND(F6>0, ((G6-F6+(F6>G6))*24)<8),8- ((G6-F6+(F6>G6))*24),0) -> 0 | W6: =((G6-F6+(F6>G6))*24) -> 0 | X6: =IF(OR(L6>0,M6>0),0,IF($F6>0,IF(AND($F6>=$X$26,$F6<=$Y$26),8,0),IF(AND($C6>=$X$26,$C6<=$Y$26),ROUND(H6,0),0))) -> 0 | Y6: =IF(OR(M6>0, L6>0),0,IF(OR(AND($C6>$X$24,$C6<$Y$24,OR($D6>$Y$24,D6>=$Z$24)),(AND($F6>$X$24,$F6<$Y$24,OR($G6>$Y$24,G6>=$Z$24)))),ROUND(H6,0),0)) -> 8 | Z6: =IF(OR(M6>0,L6>0),0,IF($F6>0,IF(OR($F6>=$X$23,AND($Z$23<$F6,$F6<$Y$23)),8,0),IF($C6>0,IF(OR($C6>=$X$23,AND($Z$23<$C6,$C6<$Y$23)),ROUND(H6,0),0),0))) -> 0 | AA6: =IF(OR(L6>0,M6>0),0,IF($F6>0,IF(OR(AND($F6>$X$25,$F6<$Y$25),AND($G6>$X$25,$G6<$Y$25)),1,0),IF($C6>0,IF(OR(AND($C6>$X$25,$C6<$Y$25),AND($D6>$X$25,$D6<$Y$25)),1,0),0))) -> 0 | AB6: =IF(F6>0,F6+(8/24),IF(C6>0,C6+(8/24),0)) -> 1.0159722 | AC6: =IF(IF(K6>0,VLOOKUP(K6,Sheet1!$A$3:$B$27,2,FALSE)-E6,0)>0,IF(K6>0,VLOOKUP(K6,Sheet1!$A$3:$B$27,2,FALSE)-E6,0),0) -> 0.7
A7: =A6+1 -> 44301 | B7: Thu | C7: 0.70208333 | D7: 0.090972222 | E7: =((D7-C7+(C7>D7))*24) -> 9.3333333 | H7: =IF(OR(M7>0,N7>0),0,IF(W7>8,8,($E7-$T7))) -> 8 | I7: =IF(G7<F7,($I$1-F7)*24,IF(D7<C7,($I$1-C7)*24,0)) -> 7.15 | J7: =IF(I6>0, IF(F6>0, W6-I6, E6-I6),0) -> 0.68333333 | Q7: =IF(V7>0,R7-V7,R7) -> 0 | R7: =IF(F7=0,"0",IF(F7>C7,(24*TEXT(F7-C7,"HH:MM")), (24*TEXT(D7-G7,"HH:MM")))) -> 0 | S7: =IF(M7>0,0,IF(I7>0,IF(I7>8,(I7-8),0),T7))+IF(AND(I6>0,T6>0),IF(I6>8,(T6-(I6-8)),T6),0) -> 0.3 | T7: =IF(M7>0,0,IF($W7>8,$W7-8,(IF(E7>8,E7-8,0)))) -> 1.3333333 | U7: =Q7+T7 -> 1.3333333 | V7: =IF(AND(F7>0, ((G7-F7+(F7>G7))*24)<8),8- ((G7-F7+(F7>G7))*24),0) -> 0 | W7: =((G7-F7+(F7>G7))*24) -> 0 | X7: =IF(OR(L7>0,M7>0),0,IF($F7>0,IF(AND($F7>=$X$26,$F7<=$Y$26),8,0),IF(AND($C7>=$X$26,$C7<=$Y$26),ROUND(H7,0),0))) -> 0 | Y7: =IF(OR(M7>0, L7>0),0,IF(OR(AND($C7>$X$24,$C7<$Y$24,OR($D7>$Y$24,D7>=$Z$24)),(AND($F7>$X$24,$F7<$Y$24,OR($G7>$Y$24,G7>=$Z$24)))),ROUND(H7,0),0)) -> 8 | Z7: =IF(OR(M7>0,L7>0),0,IF($F7>0,IF(OR($F7>=$X$23,AND($Z$23<$F7,$F7<$Y$23)),8,0),IF($C7>0,IF(OR($C7>=$X$23,AND($Z$23<$C7,$C7<$Y$23)),ROUND(H7,0),0),0))) -> 0 | AA7: =IF(OR(L7>0,M7>0),0,IF($F7>0,IF(OR(AND($F7>$X$25,$F7<$Y$25),AND($G7>$X$25,$G7<$Y$25)),1,0),IF($C7>0,IF(OR(AND($C7>$X$25,$C7<$Y$25),AND($D7>$X$25,$D7<$Y$25)),1,0),0))) -> 1 | AB7: =IF(F7>0,F7+(8/24),IF(C7>0,C7+(8/24),0)) -> 1.0354167 | AC7: =IF(IF(K7>0,VLOOKUP(K7,Sheet1!$A$3:$B$27,2,FALSE)-E7,0)>0,IF(K7>0,VLOOKUP(K7,Sheet1!$A$3:$B$27,2,FALSE)-E7,0),0) -> 0
A8: =A7+1 -> 44302 | B8: Fri | C8: 0.86597222 | D8: 0.22847222 | E8: =((D8-C8+(C8>D8))*24) -> 8.7 | H8: =IF(OR(M8>0,N8>0),0,IF(W8>8,8,($E8-$T8))) -> 8 | I8: =IF(G8<F8,($I$1-F8)*24,IF(D8<C8,($I$1-C8)*24,0)) -> 3.2166667 | J8: =IF(I7>0, IF(F7>0, W7-I7, E7-I7),0) -> 2.1833333 | Q8: =IF(V8>0,R8-V8,R8) -> 0 | R8: =IF(F8=0,"0",IF(F8>C8,(24*TEXT(F8-C8,"HH:MM")), (24*TEXT(D8-G8,"HH:MM")))) -> 0 | S8: =IF(M8>0,0,IF(I8>0,IF(I8>8,(I8-8),0),T8))+IF(AND(I7>0,T7>0),IF(I7>8,(T7-(I7-8)),T7),0) -> 1.3333333 | T8: =IF(M8>0,0,IF($W8>8,$W8-8,(IF(E8>8,E8-8,0)))) -> 0.7 | U8: =Q8+T8 -> 0.7 | V8: =IF(AND(F8>0, ((G8-F8+(F8>G8))*24)<8),8- ((G8-F8+(F8>G8))*24),0) -> 0 | W8: =((G8-F8+(F8>G8))*24) -> 0 | X8: =IF(OR(L8>0,M8>0),0,IF($F8>0,IF(AND($F8>=$X$26,$F8<=$Y$26),8,0),IF(AND($C8>=$X$26,$C8<=$Y$26),IF(I15>0,ROUND(I15,0), ROUND(H8,0)),0))) -> 0 | Y8: =IF(OR(M8>0, L8>0),0,IF(OR(AND($C8>$X$24,$C8<$Y$24,OR($D8>$Y$24,D8>=$Z$24)),(AND($F8>$X$24,$F8<$Y$24,OR($G8>$Y$24,G8>=$Z$24)))),IF(I8>0,ROUND(I8,0),ROUND(H8,0)),0)) -> 0 | Z8: =IF(OR(M8>0,L8>0),0,IF($F8>0,IF(OR($F8>=$X$23,AND($Z$23<$F8,$F8<$Y$23)),8,0),IF($C8>0,IF(OR($C8>=$X$23,AND($Z$23<$C8,$C8<$Y$23)),IF(I8>0,ROUND(I8,0), ROUND(H8,0)),0),0))) -> 3 | AA8: =IF(OR(L8>0,M8>0),0,IF($F8>0,IF(OR(AND($F8>$X$25,$F8<$Y$25),AND($G8>$X$25,$G8<$Y$25)),1,0),IF($C8>0,IF(OR(AND($C8>$X$25,$C8<$Y$25),AND($D8>$X$25,$D8<$Y$25)),1,0),0))) -> 0 | AB8: =IF(F8>0,F8+(8/24),IF(C8>0,C8+(8/24),0)) -> 1.1993056 | AC8: =IF(IF(K8>0,VLOOKUP(K8,Sheet1!$A$3:$B$27,2,FALSE)-E8,0)>0,IF(K8>0,VLOOKUP(K8,Sheet1!$A$3:$B$27,2,FALSE)-E8,0),0) -> 0
A9: =A8+1 -> 44303 | B9: Sat | C9: 0.74513889 | D9: 0.052083333 | E9: =((D9-C9+(C9>D9))*24) -> 7.3666667 | H9: =IF(OR(M9>0,N9>0),0,IF(W9>8,8,($E9-$T9))) -> 7.3666667 | I9: =IF(G9<F9,($I$1-F9)*24,IF(D9<C9,($I$1-C9)*24,0)) -> 6.1166667 | J9: =IF(I8>0, IF(F8>0, W8-I8, E8-I8),0) -> 5.4833333 | K9: 322-338 | Q9: =IF(V9>0,R9-V9,R9) -> 0 | R9: =IF(F9=0,"0",IF(F9>C9,(24*TEXT(F9-C9,"HH:MM")), (24*TEXT(D9-G9,"HH:MM")))) -> 0 | S9: =IF(M9>0,0,IF(I9>0,IF(I9>8,(I9-8),0),T9))+IF(AND(I8>0,T8>0),IF(I8>8,(T8-(I8-8)),T8),0) -> 0.7 | T9: =IF(M9>0,0,IF($W9>8,$W9-8,(IF(E9>8,E9-8,0)))) -> 0 | U9: =Q9+T9 -> 0 | V9: =IF(AND(F9>0, ((G9-F9+(F9>G9))*24)<8),8- ((G9-F9+(F9>G9))*24),0) -> 0 | W9: =((G9-F9+(F9>G9))*24) -> 0 | AB9: =IF(F9>0,F9+(8/24),IF(C9>0,C9+(8/24),0)) -> 1.0784722 | AC9: =IF(IF(K9>0,VLOOKUP(K9,Sheet1!$A$3:$B$27,2,FALSE)-E9,0)>0,IF(K9>0,VLOOKUP(K9,Sheet1!$A$3:$B$27,2,FALSE)-E9,0),0) -> 2.6333333
A10: =A9+1 -> 44304 | B10: Sun | C10: 0.70763889 | D10: 0.10833333 | E10: =((D10-C10+(C10>D10))*24) -> 9.6166667 | H10: =IF(OR(M10>0,N10>0),0,IF(W10>8,8,($E10-$T10))) -> 8 | I10: =IF(G10<F10,($I$1-F10)*24,IF(D10<C10,($I$1-C10)*24,0)) -> 7.0166667 | J10: =IF(I9>0, IF(F9>0, W9-I9, E9-I9),0) -> 1.25 | Q10: =IF(V10>0,R10-V10,R10) -> 0 | R10: =IF(F10=0,"0",IF(F10>C10,(24*TEXT(F10-C10,"HH:MM")), (24*TEXT(D10-G10,"HH:MM")))) -> 0 | S10: =IF(M10>0,0,IF(I10>0,IF(I10>8,(I10-8),0),T10))+IF(AND(I9>0,T9>0),IF(I9>8,(T9-(I9-8)),T9),0) -> 0 | T10: =IF(M10>0,0,IF($W10>8,$W10-8,(IF(E10>8,E10-8,0)))) -> 1.6166667 | U10: =Q10+T10 -> 1.6166667 | V10: =IF(AND(F10>0, ((G10-F10+(F10>G10))*24)<8),8- ((G10-F10+(F10>G10))*24),0) -> 0 | W10: =((G10-F10+(F10>G10))*24) -> 0 | X10: =IF(OR(M10>0,L10>0),0,IF(I10>0,IF($F10>0,IF(AND($F10>=$X$26,$F10<=$Y$26),ROUND(8-I10,0),0),IF($C10>0,IF(AND($C10>=$X$26,$C10<=$Y$26),ROUND(8-I10,0),0),0)),0)) -> 0 | Y10: =IF(OR(M10>0,L10>0),0,IF(I10>0,IF($F10>0,IF(OR($F10>=$X$24,AND($Z$24<$F10,$F10<$Y$24)),ROUND(8-I10,0),0),IF($C10>0,IF(OR($C10>=$X$24,AND($Z$24<$C10,$C10<$Y$24)),ROUND(8-I10,0),0),0)),0)) -> 1 | Z10: =IF(OR(M10>0,L10>0),0,IF(I10>0,IF($F10>0,IF(OR($F10>=$X$23,AND($Z$23<$F10,$F10<$Y$23)),ROUND(8-I10,0),0),IF($C10>0,IF(OR($C10>=$X$23,AND($Z$23<$C10,$C10<$Y$23)),ROUND(8-I10,0),0),0)),0)) -> 0 | AA10: =IF(OR(L10>0,M10>0),0,IF(I10>0,IF($F10>0,IF(OR(AND($F10>$X$25,$F10<$Y$25),AND($G10>$X$25,$G10<$Y$25)),1,0),IF($C10>0,IF(OR(AND($C10>$X$25,$C10<$Y$25),AND($D10>$X$25,$D10<$Y$25)),1,0),0)),0)) -> 1 | AB10: =IF(F10>0,F10+(8/24),IF(C10>0,C10+(8/24),0)) -> 1.0409722 | AC10: =IF(IF(K10>0,VLOOKUP(K10,Sheet1!$A$3:$B$27,2,FALSE)-E10,0)>0,IF(K10>0,VLOOKUP(K10,Sheet1!$A$3:$B$27,2,FALSE)-E10,0),0) -> 0
A11: =A10+1 -> 44305 | B11: Mon | C11: 0.70833333 | D11: 0.041666667 | E11: =((D11-C11+(C11>D11))*24) -> 8 | H11: =IF(OR(M11>0,N11>0),0,IF(W11>8,8,($E11-$T11))) -> 8 | I11: =IF(G11<F11,($I$1-F11)*24,IF(D11<C11,($I$1-C11)*24,0)) -> 7 | J11: =IF(I10>0, IF(F10>0, W10-I10, E10-I10),0) -> 2.6 | Q11: =IF(V11>0,R11-V11,R11) -> 0 | R11: =IF(F11=0,"0",IF(F11>C11,(24*TEXT(F11-C11,"HH:MM")), (24*TEXT(D11-G11,"HH:MM")))) -> 0 | S11: =IF(M11>0,0,IF(I11>0,IF(I11>8,(I11-8),0),T11))+IF(AND(I10>0,T10>0),IF(I10>8,(T10-(I10-8)),T10),0) -> 1.6166667 | T11: =IF(M11>0,0,IF($W11>8,$W11-8,(IF(E11>8,E11-8,0)))) -> 0 | U11: =Q11+T11 -> 0 | V11: =IF(AND(F11>0, ((G11-F11+(F11>G11))*24)<8),8- ((G11-F11+(F11>G11))*24),0) -> 0 | W11: =((G11-F11+(F11>G11))*24) -> 0 | X11: =IF(OR(L11>0,M11>0),0,IF($F11>0,IF(AND($F11>=$X$26,$F11<=$Y$26),8,0),IF(AND($C11>=$X$26,$C11<=$Y$26),ROUND(H11,0),0))) -> 0 | Y11: =IF(OR(M11>0, L11>0),0,IF(OR(AND($C11>$X$24,$C11<$Y$24,OR($D11>$Y$24,D11>=$Z$24)),(AND($F11>$X$24,$F11<$Y$24,OR($G11>$Y$24,G11>=$Z$24)))),ROUND(H11,0),0)) -> 8 | Z11: =IF(OR(M11>0,L11>0),0,IF($F11>0,IF(OR($F11>=$X$23,AND($Z$23<$F11,$F11<$Y$23)),8,0),IF($C11>0,IF(OR($C11>=$X$23,AND($Z$23<$C11,$C11<$Y$23)),ROUND(H11,0),0),0))) -> 0 | AA11: =IF(OR(L11>0,M11>0),0,IF($F11>0,IF(OR(AND($F11>$X$25,$F11<$Y$25),AND($G11>$X$25,$G11<$Y$25)),1,0),IF($C11>0,IF(OR(AND($C11>$X$25,$C11<$Y$25),AND($D11>$X$25,$D11<$Y$25)),1,0),0))) -> 0 | AB11: =IF(F11>0,F11+(8/24),IF(C11>0,C11+(8/24),0)) -> 1.0416667 | AC11: =IF(IF(K11>0,VLOOKUP(K11,Sheet1!$A$3:$B$27,2,FALSE)-E11,0)>0,IF(K11>0,VLOOKUP(K11,Sheet1!$A$3:$B$27,2,FALSE)-E11,0),0) -> 0
A12: =A11+1 -> 44306 | B12: Tue | C12: 0.83472222 | D12: 0.21875 | E12: =((D12-C12+(C12>D12))*24) -> 9.2166667 | H12: =IF(OR(M12>0,N12>0),0,IF(W12>8,8,($E12-$T12))) -> 8 | I12: =IF(G12<F12,($I$1-F12)*24,IF(D12<C12,($I$1-C12)*24,0)) -> 3.9666667 | J12: =IF(I11>0, IF(F11>0, W11-I11, E11-I11),0) -> 1 | K12: 290-322 | M12: =IF($F$41<0,(IF(AND($E12>0,(COUNT($C$3:$C12)>10)),$E12,0)),(IF(AND($E12>0,(COUNT($C$3:$C12)>9)),$E12,0))) -> 0 | Q12: =IF(V12>0,R12-V12,R12) -> 0 | R12: =IF(F12=0,"0",IF(F12>C12,(24*TEXT(F12-C12,"HH:MM")), (24*TEXT(D12-G12,"HH:MM")))) -> 0 | S12: =IF(M12>0,0,IF(I12>0,IF(I12>8,(I12-8),0),T12))+IF(AND(I11>0,T11>0),IF(I11>8,(T11-(I11-8)),T11),0) -> 0 | T12: =IF(M12>0,0,IF($W12>8,$W12-8,(IF(E12>8,E12-8,0)))) -> 1.2166667 | U12: =Q12+T12 -> 1.2166667 | V12: =IF(AND(F12>0, ((G12-F12+(F12>G12))*24)<8),8- ((G12-F12+(F12>G12))*24),0) -> 0 | W12: =((G12-F12+(F12>G12))*24) -> 0 | X12: =IF(OR(L12>0,M12>0),0,IF($F12>0,IF(AND($F12>=$X$26,$F12<=$Y$26),8,0),IF(AND($C12>=$X$26,$C12<=$Y$26),ROUND(H12,0),0))) -> 0 | Y12: =IF(OR(M12>0, L12>0),0,IF(OR(AND($C12>$X$24,$C12<$Y$24,OR($D12>$Y$24,D12>=$Z$24)),(AND($F12>$X$24,$F12<$Y$24,OR($G12>$Y$24,G12>=$Z$24)))),ROUND(H12,0),0)) -> 0 | Z12: =IF(OR(M12>0,L12>0),0,IF($F12>0,IF(OR($F12>=$X$23,AND($Z$23<$F12,$F12<$Y$23)),8,0),IF($C12>0,IF(OR($C12>=$X$23,AND($Z$23<$C12,$C12<$Y$23)),ROUND(H12,0),0),0))) -> 8 | AA12: =IF(OR(L12>0,M12>0),0,IF($F12>0,IF(OR(AND($F12>$X$25,$F12<$Y$25),AND($G12>$X$25,$G12<$Y$25)),1,0),IF($C12>0,IF(OR(AND($C12>$X$25,$C12<$Y$25),AND($D12>$X$25,$D12<$Y$25)),1,0),0))) -> 0 | AB12: =IF(F12>0,F12+(8/24),IF(C12>0,C12+(8/24),0)) -> 1.1680556 | AC12: =IF(IF(K12>0,VLOOKUP(K12,Sheet1!$A$3:$B$27,2,FALSE)-E12,0)>0,IF(K12>0,VLOOKUP(K12,Sheet1!$A$3:$B$27,2,FALSE)-E12,0),0) -> 0
A13: =A12+1 -> 44307 | B13: Wed | C13: 0.89583333 | D13: 0.22916667 | E13: =((D13-C13+(C13>D13))*24) -> 8 | H13: =IF(OR(M13>0,N13>0),0,IF(W13>8,8,($E13-$T13))) -> 0 | I13: =IF(G13<F13,($I$1-F13)*24,IF(D13<C13,($I$1-C13)*24,0)) -> 2.5 | J13: =IF(I12>0, IF(F12>0, W12-I12, E12-I12),0) -> 5.25 | M13: =IF($F$41<0,(IF(AND($E13>0,(COUNT($C$3:$C13)>10)),$E13,0)),(IF(AND($E13>0,(COUNT($C$3:$C13)>9)),$E13,0))) -> 8 | Q13: =IF(V13>0,R13-V13,R13) -> 0 | R13: =IF(F13=0,"0",IF(F13>C13,(24*TEXT(F13-C13,"HH:MM")), (24*TEXT(D13-G13,"HH:MM")))) -> 0 | S13: =IF(M13>0,0,IF(I13>0,IF(I13>8,(I13-8),0),T13))+IF(AND(I12>0,T12>0),IF(I12>8,(T12-(I12-8)),T12),0) -> 1.2166667 | T13: =IF(M13>0,0,IF($W13>8,$W13-8,(IF(E13>8,E13-8,0)))) -> 0 | U13: =Q13+T13 -> 0 | V13: =IF(AND(F13>0, ((G13-F13+(F13>G13))*24)<8),8- ((G13-F13+(F13>G13))*24),0) -> 0 | W13: =((G13-F13+(F13>G13))*24) -> 0 | X13: =IF(OR(L13>0,M13>0),0,IF($F13>0,IF(AND($F13>=$X$26,$F13<=$Y$26),8,0),IF(AND($C13>=$X$26,$C13<=$Y$26),ROUND(H13,0),0))) -> 0 | Y13: =IF(OR(M13>0, L13>0),0,IF(OR(AND($C13>$X$24,$C13<$Y$24,OR($D13>$Y$24,D13>=$Z$24)),(AND($F13>$X$24,$F13<$Y$24,OR($G13>$Y$24,G13>=$Z$24)))),ROUND(H13,0),0)) -> 0 | Z13: =IF(OR(M13>0,L13>0),0,IF($F13>0,IF(OR($F13>=$X$23,AND($Z$23<$F13,$F13<$Y$23)),8,0),IF($C13>0,IF(OR($C13>=$X$23,AND($Z$23<$C13,$C13<$Y$23)),ROUND(H13,0),0),0))) -> 0 | AA13: =IF(OR(L13>0,M13>0),0,IF($F13>0,IF(OR(AND($F13>$X$25,$F13<$Y$25),AND($G13>$X$25,$G13<$Y$25)),1,0),IF($C13>0,IF(OR(AND($C13>$X$25,$C13<$Y$25),AND($D13>$X$25,$D13<$Y$25)),1,0),0))) -> 0 | AB13: =IF(F13>0,F13+(8/24),IF(C13>0,C13+(8/24),0)) -> 1.2291667 | AC13: =IF(IF(K13>0,VLOOKUP(K13,Sheet1!$A$3:$B$27,2,FALSE)-E13,0)>0,IF(K13>0,VLOOKUP(K13,Sheet1!$A$3:$B$27,2,FALSE)-E13,0),0) -> 0
A14: =A13+1 -> 44308 | B14: Thu | C14: 0.70069444 | D14: 0.99236111 | E14: =((D14-C14+(C14>D14))*24) -> 7 | H14: =IF(OR(M14>0,N14>0),0,IF(W14>8,8,($E14-$T14))) -> 0 | I14: =IF(G14<F14,($I$1-F14)*24,IF(D14<C14,($I$1-C14)*24,0)) -> 0 | J14: =IF(I13>0, IF(F13>0, W13-I13, E13-I13),0) -> 5.5 | M14: =IF($F$41<0,(IF(AND($E14>0,(COUNT($C$3:$C14)>10)),$E14,0)),(IF(AND($E14>0,(COUNT($C$3:$C14)>9)),$E14,0))) -> 7 | Q14: =IF(V14>0,R14-V14,R14) -> 0 | R14: =IF(F14=0,"0",IF(F14>C14,(24*TEXT(F14-C14,"HH:MM")), (24*TEXT(D14-G14,"HH:MM")))) -> 0 | S14: =IF(M14>0,0,IF(I14>0,IF(I14>8,(I14-8),0),T14))+IF(AND(I13>0,T13>0),IF(I13>8,(T13-(I13-8)),T13),0) -> 0 | T14: =IF(M14>0,0,IF($W14>8,$W14-8,(IF(E14>8,E14-8,0)))) -> 0 | U14: =Q14+T14 -> 0 | V14: =IF(AND(F14>0, ((G14-F14+(F14>G14))*24)<8),8- ((G14-F14+(F14>G14))*24),0) -> 0 | W14: =((G14-F14+(F14>G14))*24) -> 0 | X14: =IF(OR(L14>0,M14>0),0,IF($F14>0,IF(AND($F14>=$X$26,$F14<=$Y$26),8,0),IF(AND($C14>=$X$26,$C14<=$Y$26),ROUND(H14,0),0))) -> 0 | Y14: =IF(OR(M14>0, L14>0),0,IF(OR(AND($C14>$X$24,$C14<$Y$24,OR($D14>$Y$24,D14>=$Z$24)),(AND($F14>$X$24,$F14<$Y$24,OR($G14>$Y$24,G14>=$Z$24)))),ROUND(H14,0),0)) -> 0 | Z14: =IF(OR(M14>0,L14>0),0,IF($F14>0,IF(OR($F14>=$X$23,AND($Z$23<$F14,$F14<$Y$23)),8,0),IF($C14>0,IF(OR($C14>=$X$23,AND($Z$23<$C14,$C14<$Y$23)),ROUND(H14,0),0),0))) -> 0 | AA14: =IF(OR(L14>0,M14>0),0,IF($F14>0,IF(OR(AND($F14>$X$25,$F14<$Y$25),AND($G14>$X$25,$G14<$Y$25)),1,0),IF($C14>0,IF(OR(AND($C14>$X$25,$C14<$Y$25),AND($D14>$X$25,$D14<$Y$25)),1,0),0))) -> 0 | AB14: =IF(F14>0,F14+(8/24),IF(C14>0,C14+(8/24),0)) -> 1.0340278 | AC14: =IF(IF(K14>0,VLOOKUP(K14,Sheet1!$A$3:$B$27,2,FALSE)-E14,0)>0,IF(K14>0,VLOOKUP(K14,Sheet1!$A$3:$B$27,2,FALSE)-E14,0),0) -> 0
A15: =A14+1 -> 44309 | B15: Fri | C15: 0.62013889 | D15: 0.93402778 | E15: =((D15-C15+(C15>D15))*24) -> 7.5333333 | H15: =IF(OR(M15>0,N15>0),0,IF(W15>8,8,($E15-$T15))) -> 0 | I15: =IF(G15<F15,($I$1-F15)*24,IF(D15<C15,($I$1-C15)*24,0)) -> 0 | J15: =IF(I14>0, IF(F14>0, W14-I14, E14-I14),0) -> 0 | M15: =IF($F$41<0,(IF(AND($E15>0,(COUNT($C$3:$C15)>10)),IF(I15>0,I15,$E15),0)),(IF(AND($E15>0,(COUNT($C$3:$C15)>9)),IF(I15>0,I15,$E15),0))) -> 7.5333333 | Q15: =IF(V15>0,R15-V15,R15) -> 0 | R15: =IF(F15=0,"0",IF(F15>C15,(24*TEXT(F15-C15,"HH:MM")), (24*TEXT(D15-G15,"HH:MM")))) -> 0 | S15: =IF(M15>0,0,IF(I15>0,IF(I15>8,(I15-8),0),T15))+IF(AND(I14>0,T14>0),IF(I14>8,(T14-(I14-8)),T14),0) -> 0 | T15: =IF(M15>0,0,IF($W15>8,$W15-8,(IF(E15>8,E15-8,0)))) -> 0 | U15: =Q15+T15 -> 0 | V15: =IF(AND(F15>0, ((G15-F15+(F15>G15))*24)<8),8- ((G15-F15+(F15>G15))*24),0) -> 0 | W15: =((G15-F15+(F15>G15))*24) -> 0 | X15: =IF(OR(L15>0,M15>0),0,IF($F15>0,IF(AND($F15>=$X$26,$F15<=$Y$26),8,0),IF(AND($C15>=$X$26,$C15<=$Y$26),IF(I22>0,ROUND(I22,0), ROUND(H15,0)),0))) -> 0 | Y15: =IF(OR(M15>0, L15>0),0,IF(OR(AND($C15>$X$24,$C15<$Y$24,OR($D15>$Y$24,D15>=$Z$24)),(AND($F15>$X$24,$F15<$Y$24,OR($G15>$Y$24,G15>=$Z$24)))),IF(I15>0,ROUND(I15,0),ROUND(H15,0)),0)) -> 0 | Z15: =IF(OR(M15>0,L15>0),0,IF($F15>0,IF(OR($F15>=$X$23,AND($Z$23<$F15,$F15<$Y$23)),8,0),IF($C15>0,IF(OR($C15>=$X$23,AND($Z$23<$C15,$C15<$Y$23)),IF(I15>0,ROUND(I15,0), ROUND(H15,0)),0),0))) -> 0 | AA15: =IF(OR(L15>0,M15>0),0,IF($F15>0,IF(OR(AND($F15>$X$25,$F15<$Y$25),AND($G15>$X$25,$G15<$Y$25)),1,0),IF($C15>0,IF(OR(AND($C15>$X$25,$C15<$Y$25),AND($D15>$X$25,$D15<$Y$25)),1,0),0))) -> 0 | AB15: =IF(F15>0,F15+(8/24),IF(C15>0,C15+(8/24),0)) -> 0.95347222 | AC15: =IF(IF(K15>0,VLOOKUP(K15,Sheet1!$A$3:$B$27,2,FALSE)-E15,0)>0,IF(K15>0,VLOOKUP(K15,Sheet1!$A$3:$B$27,2,FALSE)-E15,0),0) -> 0
A16: =A15+1 -> 44310 | B16: Sat | E16: =((D16-C16+(C16>D16))*24) -> 0 | H16: =IF(OR(M16>0,N16>0),0,IF(W16>8,8,($E16-$T16))) -> 0 | I16: =IF(G16<F16,($I$1-F16)*24,IF(D16<C16,($I$1-C16)*24,0)) -> 0 | J16: =IF(I15>0, IF(F15>0, W15-I15, E15-I15),0) -> 0 | M16: =IF(M15>0,J16,0)+IF($F$41<0,(IF(AND($E16>0,(COUNT($C$3:$C16)>10)),$E16,0)),(IF(AND($E16>0,(COUNT($C$3:$C16)>9)),$E16,0))) -> 0 | Q16: =IF(V16>0,R16-V16,R16) -> 0 | R16: =IF(F16=0,"0",IF(F16>C16,(24*TEXT(F16-C16,"HH:MM")), (24*TEXT(D16-G16,"HH:MM")))) -> 0 | S16: =IF(M16>0,0,IF(I16>0,IF(I16>8,(I16-8),0),T16))+IF(AND(I15>0,T15>0),IF(I15>8,(T15-(I15-8)),T15),0) -> 0 | T16: =IF(M16>0,0,IF($W16>8,$W16-8,(IF(E16>8,E16-8,0)))) -> 0 | U16: =Q16+T16 -> 0 | V16: =IF(AND(F16>0, ((G16-F16+(F16>G16))*24)<8),8- ((G16-F16+(F16>G16))*24),0) -> 0 | W16: =((G16-F16+(F16>G16))*24) -> 0 | AB16: =IF(F16>0,F16+(8/24),IF(C16>0,C16+(8/24),0)) -> 0 | AC16: =IF(IF(K16>0,VLOOKUP(K16,Sheet1!$A$3:$B$27,2,FALSE)-E16,0)>0,IF(K16>0,VLOOKUP(K16,Sheet1!$A$3:$B$27,2,FALSE)-E16,0),0) -> 0
A17: TOTAL | E17: =SUM(E3:E16) -> 100.93333 | H17: =SUM(H3:H16) -> 71.366667 | I17: =SUM(I3:I16) -> 58.416667 | J17: =SUM(J3:J16) -> 27.983333 | L17: =SUM(L3:L11)+IF(M12>0,0,L12)+IF(M13>0,0,L13)+IF(M14>0,0,L14)+IF(M15>0,0,L15)+IF(M16>0,0,L16) -> 0 | M17: =SUM(M3:M16) -> 22.533333 | N17: =SUM(N3:N16) -> 0 | O17: =SUM(O3:O16) -> 0 | P17: =SUM(P3:P16) -> 0 | Q17: =SUM(Q11:Q15)+SUM(Q4:Q8) -> 0 | R17: =SUM(R11:R15)+SUM(R4:R8) -> 0 | S17: =SUM(S3:S16) -> 7.0333333 | T17: =SUM(T3:T16) -> 7.0333333 | U17: =SUM(U11:U15)+SUM(U4:U8) -> 4.1 | V17: =SUM(V3:V16) -> 0 | W17: =SUM(W3:W16) -> 0 | X17: =SUM(X3:X16) -> 0 | Y17: =SUM(Y3:Y16) -> 34 | Z17: =SUM(Z3:Z16) -> 11 | AA17: =SUM(AA3:AA16) -> 4 | AC17: =SUM(AC3:AC16) -> 4.0166667
M18: =COUNTIF(M12:M16,">0") -> 3
A19: *For buildup, enter only rostered times, not actual shift
A20: *For Security Allowance, Guarantee , WOBOD and ADO make manual entries
A21: PAY CALCULATOR
A22: CODE | B22: DESCRIPTION | E22: RATE | F22: PAY | X22: Start | Y22: End | Z22: Midnight
A23: 1001 | B23: Ordinary Hours | E23: 35.19605 | F23: =H17*E23 -> 2511.8248 | X23: 0.75 | Y23: 0.16666667 | Z23: 0
A24: 5003/1010 | B24: Sick Leave/PHNW | E24: =E23 -> 35.19605 | F24: =O17*E24 -> 0 | X24: 0.41666667 | Y24: 0.75 | Z24: 0
A25: 5000/5400 | B25: Annual Leave | E25: =E23 -> 35.19605 | F25: =P17*E25 -> 0 | X25: 0.041666667 | Y25: 0.16666667
A26: 5499 | B26: Annual Leave Loading | E26: =E23*20% -> 7.03921 | F26: =P17*E26 -> 0 | X26: 0.16666667 | Y26: 0.22916667
A27: 1011 | B27: Public Holiday worked | E27: =E23*200% -> 70.3921 | F27: =N17*E27 -> 0 | X27: =(IF(M4>0,0,IF(U4>3,(U4-3),0))+IF(M5>0,0,IF(U5>3,(U5-3),0))+IF(M6>0,0,IF(U6>3,(U6-3),0))+IF(M7>0,0,IF(U7>3,(U7-3),0))+IF(M8>0,0,IF(U8>3,(U8-3),0))+IF(M11>0,0,IF(U11>3,(U11-3),0))+IF(M12>0,0,IF(U12>3,(U12-3),0))+IF(M13>0,0,IF(U13>3,(U13-3),0))+IF(M14>0,0,IF(U14>3,(U14-3),0))+IF(M15>0,0,IF(U15>3,(U15-3),0))) -> 0
A28: 1063 | B28: Public Holiday Loading | E28: =50%*E23 -> 17.598025 | F28: =N17*E28 -> 0
A29: OVERTIME
A30: 1026 | B30: Scheduled OT Weekdays (150%) | E30: =150%*E23 -> 52.794075 | F30: =(S17-S16-S10-S3-S9-X27)*E30 -> 334.36247
A31: 1027 | B31: Scheduled OT Weekdays (200%) | E31: =200%*E23 -> 70.3921 | F31: =(IF(M4>0,0,IF(U4>3,(U4-3),0))+IF(M5>0,0,IF(U5>3,(U5-3),0))+IF(M6>0,0,IF(U6>3,(U6-3),0))+IF(M7>0,0,IF(U7>3,(U7-3),0))+IF(M8>0,0,IF(U8>3,(U8-3),0))+IF(M11>0,0,IF(U11>3,(U11-3),0))+IF(M12>0,0,IF(U12>3,(U12-3),0))+IF(M13>0,0,IF(U13>3,(U13-3),0))+IF(M14>0,0,IF(U14>3,(U14-3),0))+IF(M15>0,0,IF(U15>3,(U15-3),0)))*E31 -> 0
A32: 1027 | B32: Saturday OT (200%) | E32: =E23*200% -> 70.3921 | F32: =(S9+Q9+S16+Q16)*E32 -> 49.27447
A33: 1027 | B33: Sunday OT (200%) | E33: =E23*200% -> 70.3921 | F33: =(Q3+Q10+S3+S10)*E33 -> 0
A34: 1064 | B34: Saturday Loading (50%) | E34: =E23*50% -> 17.598025 | F34: =(J16+J9-S9-S16+IF(M16>0,0,IF(I16>0,I16,MIN(E16,8)))+IF(I9>0,I9,MIN(E9,8)))*E34 -> 191.81847
A35: 1076 | B35: Sunday Loading (100%) | E35: =E23 -> 35.19605 | F35: =(J3+J10-S3-S10+IF(I3>0,I3,MIN(E3,8))+IF(I10>0,I10,MIN(E10,8)))*E35 -> 537.32636
A36: 1100 | B36: Extra Shifts (upto 12 days) | E36: =E23*150% -> 52.794075 | F36: =(IF(M12>0,M12,0)+IF(M13>0,M13,0)+IF(AND(M14>0,(COUNTIF(M12:M13,">0")<2)),M14,0)+IF(AND(M15>0,(COUNTIF(M12:M14,">0")<2)),M15,0))*E36 -> 791.91112
B37: Extra Shifts Weekend | E37: =200%*E23 -> 70.3921 | F37: =IF(AND(M16>0,M18<3),M16*E37,0) -> 0
A38: 1105 | B38: Extra shifts (beyond 12 days) | E38: =200%*E23 -> 70.3921 | F38: =(IF(AND(M17>0,M18>2),M16,0)+IF(AND(M17>0,M18>2,M16=0),M15,0)+IF(AND(M17>0,M18>3),M15,0))*E38 -> 530.28715
A39: 1156 | B39: Callout Allowance | E39: =E23*25% -> 8.7990125 | F39: =L17*E39 -> 0
A40: 1435&1442 | B40: Electric Guards Allowance | E40: 13.15 | F40: =E40*10 -> 131.5
...
